## 1. Error 实例对象 [#](https://wangdoc.com/javascript/features/error.html#error-实例对象)

JavaScript 解析或运行时，一旦发生错误，引擎就会抛出一个错误对象。JavaScript 原生提供`Error`构造函数，所有抛出的错误都是这个构造函数的实例。

```javascript
var err = new Error('出错了');
err.message // "出错了"
```

大多数 JavaScript 引擎，对`Error`实例还提供`name`和`stack`属性，分别表示错误的名称和错误的堆栈，但它们是非标准的，不是每种实现都有。

- **message**：错误提示信息
- **name**：错误名称（非标准属性）
- **stack**：错误的堆栈（非标准属性）

使用`name`和`message`这两个属性，可以对发生什么错误有一个大概的了解。

```javascript
if (error.name) {
  console.log(error.name + ': ' + error.message);
}
```

`stack`属性用来查看错误发生时的堆栈。

```javascript
function throwit() {
  throw new Error('');
}

function catchit() {
  try {
    throwit();
  } catch(e) {
    console.log(e.stack); // print stack trace
  }
}

catchit()
// Error
//    at throwit (~/examples/throwcatch.js:9:11)
//    at catchit (~/examples/throwcatch.js:3:9)
//    at repl:1:5
```

上面代码中，错误堆栈的最内层是`throwit`函数，然后是`catchit`函数，最后是函数的运行环境。

## 2. 原生错误类型

`Error`实例对象是最一般的错误类型，在它的基础上，JavaScript 还定义了其他6种错误对象。也就是说，存在`Error`的6个派生对象。

### SyntaxError 对象

`SyntaxError`对象是解析代码时发生的语法错误。

```javascript
// 变量名错误
var 1a;
// Uncaught SyntaxError: Invalid or unexpected token

// 缺少括号
console.log 'hello');
// Uncaught SyntaxError: Unexpected string
```

### ReferenceError 对象

`ReferenceError`对象是引用一个不存在的变量时发生的错误。

```javascript
// 使用一个不存在的变量
unknownVariable
// Uncaught ReferenceError: unknownVariable is not defined
```

另一种触发场景是，将一个值分配给无法分配的对象，比如对函数的运行结果赋值。

```javascript
// 等号左侧不是变量
console.log() = 1
// Uncaught ReferenceError: Invalid left-hand side in assignment
```

### RangeError 对象

`RangeError`对象是一个值超出有效范围时发生的错误。主要有几种情况，一是数组长度为负数，二是`Number`对象的方法参数超出范围，以及函数堆栈超过最大值。

```javascript
// 数组长度不得为负数
new Array(-1)
// Uncaught RangeError: Invalid array length
```

### TypeError 对象

`TypeError`对象是变量或参数不是预期类型时发生的错误。比如，对字符串、布尔值、数值等原始类型的值使用`new`命令，就会抛出这种错误，因为`new`命令的参数应该是一个构造函数。

```javascript
new 123
// Uncaught TypeError: number is not a func

var obj = {};
obj.unknownMethod()
// Uncaught TypeError: obj.unknownMethod is not a function
```

### URIError 对象

`URIError`对象是 URI 相关函数的参数不正确时抛出的错误，主要涉及`encodeURI()`、`decodeURI()`、`encodeURIComponent()`、`decodeURIComponent()`、`escape()`和`unescape()`这六个函数。

```javascript
decodeURI('%2')
// URIError: URI malformed
```

### EvalError 对象

`eval`函数没有被正确执行时，会抛出`EvalError`错误。该错误类型已经不再使用了，只是为了保证与以前代码兼容，才继续保留。

### 总结

以上这6种派生错误，连同原始的`Error`对象，都是构造函数。开发者可以使用它们，手动生成错误对象的实例。这些构造函数都接受一个参数，代表错误提示信息（message）。

```javascript
var err1 = new Error('出错了！');
var err2 = new RangeError('出错了，变量超出有效范围！');
var err3 = new TypeError('出错了，变量类型无效！');

err1.message // "出错了！"
err2.message // "出错了，变量超出有效范围！"
err3.message // "出错了，变量类型无效！"
```

## 3. 自定义错误

```javascript
function UserError(message) {
  this.message = message || '默认信息';
  this.name = 'UserError';
}

UserError.prototype = new Error();
UserError.prototype.constructor = UserError;
```

上面代码自定义一个错误对象`UserError`，让它继承`Error`对象。然后，就可以生成这种自定义类型的错误了。

```javascript
new UserError('这是自定义的错误！');
```

## 4. throw 语句

`throw`语句的作用是手动中断程序执行，抛出一个错误。

```javascript
if (x <= 0) {
  throw new Error('x 必须为正数');
}
// Uncaught ReferenceError: x is not defined
```

实际上，`throw`可以抛出任何类型的值。也就是说，它的参数可以是任何值。

```javascript
// 抛出一个字符串
throw 'Error！';
// Uncaught Error！

// 抛出一个数值
throw 42;
// Uncaught 42

// 抛出一个布尔值
throw true;
// Uncaught true

// 抛出一个对象
throw {
  toString: function () {
    return 'Error!';
  }
};
// Uncaught {toString: ƒ}
```

## 5. try...catch 结构

一旦发生错误，程序就中止执行了。JavaScript 提供了`try...catch`结构，允许对错误进行处理，选择是否往下执行。

```javascript
try {
  throw new Error('出错了!');
} catch (e) {
  console.log(e.name + ": " + e.message);
  console.log(e.stack);
}
// Error: 出错了!
//   at <anonymous>:3:9
//   ...
```

上面代码中，`try`代码块抛出错误（上例用的是`throw`语句），JavaScript 引擎就立即把代码的执行，转到`catch`代码块，或者说错误被`catch`代码块捕获了。`catch`接受一个参数，表示`try`代码块抛出的值。

如果你不确定某些代码是否会报错，就可以把它们放在`try...catch`代码块之中，便于进一步对错误进行处理。

```javascript
try {
  f();
} catch(e) {
  // 处理错误
}
```

上面代码中，如果函数`f`执行报错，就会进行`catch`代码块，接着对错误进行处理。

`catch`代码块捕获错误之后，程序不会中断，会按照正常流程继续执行下去。

```javascript
try {
  throw "出错了";
} catch (e) {
  console.log(111);
}
console.log(222);
// 111
// 222
```

上面代码中，`try`代码块抛出的错误，被`catch`代码块捕获后，程序会继续向下执行。

`catch`代码块之中，还可以再抛出错误，甚至使用嵌套的`try...catch`结构。

```javascript
var n = 100;

try {
  throw n;
} catch (e) {
  if (e <= 50) {
    // ...
  } else {
    throw e;
  }
}
// Uncaught 100
```

上面代码中，`catch`代码之中又抛出了一个错误。

为了捕捉不同类型的错误，`catch`代码块之中可以加入判断语句。

```javascript
try {
  foo.bar();
} catch (e) {
  if (e instanceof EvalError) {
    console.log(e.name + ": " + e.message);
  } else if (e instanceof RangeError) {
    console.log(e.name + ": " + e.message);
  }
  // ...
}
```

上面代码中，`catch`捕获错误之后，会判断错误类型（`EvalError`还是`RangeError`），进行不同的处理。